Workbook
Name Slicer_Payment_Method: #N/A
Name Slicer_Status: #N/A

Sheet in
A1: ID | B1: Customer_Name | C1: Order_ID | D1: Order_Date | E1: Product | F1: Category | G1: Quantity | H1: Price | I1: Payment_Method | J1: Status | K1: Total
A2: 100 | B2: Customer_100 | C2: ORD-41285 | D2: 11/22/2024 | E2: Blender | F2: Home | G2: 3 | H2: 38 | I2: Cash on Delivery | J2: Shipped | K2: 114
A3: 101 | B3: Customer_101 | C3: ORD-35783 | D3: 45784 | E3: Smartphone | F3: Electronics | G3: 2 | H3: abd | I3: PayPal | J3: Processing
A4: 102 | B4: Customer_102 | C4: ORD-84355 | D4: 12/23/2024 | E4: Tennis Racket | F4: Sports | G4: 1 | H4: 389.05 | I4: PayPal | J4: Delivered | K4: 389.05
A5: 103 | B5: Customer_103 | C5: ORD-57811 | D5: 3/19/2025 | E5: Science | F5: Books | G5: 5 | H5: 233.92 | I5: PayPal | J5: Processing | K5: 1169.6
A6: 104 | B6: Customer_104 | C6: ORD-93614 | D6: 10/20/2025 | E6: Biography | F6: Books | G6: 1 | H6: 552.51 | I6: Cash on Delivery | J6: Processing | K6: 552.51
A7: 105 | B7: Customer_105 | C7: ORD-22442 | D7: 11/20/2024 | E7: Tennis Racket | F7: Sports | G7: 3 | H7: 122.06 | I7: Cash on Delivery | J7: Cancelled | K7: 366.18
A8: 106 | B8: Customer_106 | C8: ORD-25885 | D8: 45690 | E8: Blender | F8: Home | H8: 978.63 | I8: Bank Transfer | J8: Processing
A9: 107 | B9: Customer_107 | C9: ORD-89122 | D9: 45717 | E9: Biography | F9: Books | G9: 5 | H9: 587.68 | I9: PayPal | J9: Returned | K9: 2938.4
A10: 108 | B10: Customer_108 | C10: ORD-64400 | D10: 10/23/2025 | E10: Science | F10: Books | G10: 1 | H10: 600.29 | I10: Cash on Delivery | J10: Processing | K10: 600.29
A11: 109 | B11: Customer_109 | C11: ORD-18512 | D11: 45721 | E11: Tennis Racket | F11: Sports | G11: 5 | H11: 168.34 | I11: Credit Card | J11: Shipped | K11: 841.7
A12: 110 | B12: Customer_110 | C12: ORD-61020 | D12: 9/26/2025 | E12: Basketball | F12: sports | G12: 5 | H12: four hundred | I12: Cash on Delivery | J12: Cancelled
A13: 111 | B13: Customer_111 | C13: ORD-72349 | D13: 10/22/2025 | E13: Comics | F13: Books | G13: 2 | H13: 865.77 | I13: Credit Card | J13: Returned | K13: 1731.54
A14: 112 | B14: Customer_112 | C14: ORD-80867 | D14: 45691 | E14: Shoes | F14: Clothing | G14: 4 | H14: 752.13 | I14: Bank Transfer | J14: Delivered | K14: 3008.52
A15: 113 | B15: Customer_113 | C15: ORD-23994 | D15: 7/24/2025 | E15: Fiction | F15: Books | G15: 1 | H15: 411.81 | I15: Credit Card | J15: Processing | K15: 411.81
A16: 114 | B16: Customer_114 | C16: ORD-77417 | D16: Jan 5 2023 | E16: Smartphone | F16: Electronics | G16: 2 | H16: 413.13 | I16: Cash on Delivery | J16: Shipped | K16: 826.26
A17: 115 | B17: Customer_115 | C17: ORD-72778 | D17: 45931 | E17: Fiction | F17: Books | G17: 2 | H17: 796.84 | I17: Cash on Delivery | J17: Returned | K17: 1115.576
A18: 116 | B18: Customer_116 | C18: ORD-63660 | D18: 10/30/2025 | E18: Microwave | F18: Home | G18: 4 | I18: Cash on Delivery | J18: Processing
A19: 117 | B19: Customer_117 | C19: ORD-72751 | D19: 45993 | E19: Blender | F19: electronic | G19: -2 | H19: 10000 | I19: Cash on Delivery | J19: Processing | K19: -20000
A20: 118 | B20: Customer_118 | C20: ORD-96061 | D20: 5/31/2025 | E20: Science | F20: Books | G20: 5 | H20: 247.82 | I20: PayPal | J20: Processing | K20: 1239.1
A21: 119 | B21: Customer_119 | C21: ORD-76016 | D21: 12/19/2024 | E21: Basketball | F21: Sports | G21: 4 | H21: 438.19 | I21: Cash on Delivery | J21: Processing | K21: 1752.76
A22: 120 | B22: Customer_120 | C22: ORD-14659 | D22: 6/13/2025 | E22: Yoga Mat | F22: ELECTRONICS | G22: 5 | H22: 300$ | I22: Credit Card | J22: Cancelled
A23: 121 | B23: Customer_121 | C23: ORD-80067 | D23: 45971 | E23: Basketball | F23: Sports | G23: 4 | H23: 523.01 | I23: Credit Card | J23: Delivered | K23: 2092.04
A24: 122 | B24: Customer_122 | C24: ORD-21443 | D24: 5/16/2025 | E24: Microwave | F24: Home | G24: 2 | H24: 556.93 | I24: PayPal | J24: Shipped | K24: 1113.86
A25: 123 | B25: Customer_123 | C25: ORD-11314 | D25: 45818 | E25: Vacuum | F25: electronic | G25: 3 | H25: 615.91 | I25: Cash on Delivery | J25: Cancelled | K25: 1847.73
A26: 124 | B26: Customer_124 | C26: ORD-46136 | D26: 5/31/2025 | E26: Comics | F26: Books | G26: 5 | I26: PayPal | J26: Cancelled
A27: 125 | B27: Customer_125 | C27: ORD-23202 | D27: 45902 | E27: Comics | F27: Books | G27: 4 | H27: 765.69 | I27: PayPal | J27: Shipped | K27: 3062.76
A28: 126 | B28: Customer_126 | C28: ORD-11261 | D28: 5/18/2025 | E28: Shoes | F28: Clothing | G28: 4 | H28: 836.8 | I28: Bank Transfer | J28: Cancelled | K28: 3347.2
A29: 127 | B29: Customer_127 | C29: ORD-65482 | D29: 45996 | E29: Blender | F29: Home | G29: 5 | H29: 336.02 | I29: Bank Transfer | J29: Returned | K29: 1680.1
A30: 128 | B30: Customer_128 | C30: ORD-12270 | D30: 45576 | E30: Lamp | F30: electronics | G30: 3 | H30: 898.69 | I30: Bank Transfer | J30: Delivered | K30: 2696.07
A31: 129 | B31: Customer_129 | C31: ORD-48863 | D31: 6/22/2025 | E31: Science | F31: Books | G31: 4 | H31: 736.71 | I31: Bank Transfer | J31: Returned | K31: 2946.84
A32: 130 | B32: Customer_130 | C32: ORD-34007 | D32: 8/15/2025 | E32: Tennis Racket | F32: Sports | G32: 2 | I32: Bank Transfer | J32: Processing
A33: 131 | B33: Customer_131 | C33: ORD-91396 | D33: 45967 | E33: Lamp | F33: Home | G33: 5 | H33: 616.63 | I33: PayPal | J33: Shipped | K33: 3083.15
A34: 132 | B34: Customer_132 | C34: ORD-40186 | D34: 45692 | E34: Yoga Mat | F34: ELECTRONICS | G34: 1 | H34: 266.7 | I34: PayPal | J34: Delivered | K34: 266.7
A35: 133 | B35: Customer_133 | C35: ORD-68182 | D35: 45424 | E35: Biography | F35: nan | G35: 5 | H35: 343.24 | I35: Credit Card | J35: Shipped | K35: 1716.2
A36: 134 | B36: Customer_134 | C36: ORD-16585 | D36: 45757 | E36: T-shirt | F36: Clothing | G36: -5 | H36: 591.53 | I36: PayPal | J36: Shipped | K36: -2957.65
A37: 135 | B37: Customer_135 | C37: ORD-33656 | D37: 45902 | E37: Smartwatch | F37: electronics | G37: 4 | H37: 446.19 | I37: Cash on Delivery | J37: Cancelled | K37: 1784.76
A38: 136 | B38: Customer_136 | C38: ORD-20985 | D38: 45997 | E38: Headphones | G38: 1 | H38: 696.71 | I38: Credit Card | J38: Delivered | K38: 696.71
A39: 137 | B39: Customer_137 | C39: ORD-91254 | D39: 2/23/2025 | E39: Vacuum | F39: Home | G39: 3 | H39: -100 | I39: Cash on Delivery | J39: Delivered | K39: -300
A40: 138 | B40: Customer_138 | C40: ORD-34319 | D40: 45908 | E40: Lamp | F40: Home | G40: 1 | H40: 531.06 | I40: PayPal | J40: Processing | K40: 531.06
...

Sheet clean data
A1: ID | B1: Customer_Name | C1: Order_ID | D1: Order_Date | E1: Product | F1: Category | G1: Quantity | H1: Price | I1: Payment_Method | J1: Status | K1: Total
A2: =in!A2 -> 100 | B2: =TRIM(in!B2) -> Customer_100 | C2: =in!C2 -> ORD-41285 | D2: =IFERROR(DATEVALUE(in!D2),in!D2) -> 11/22/2024 | E2: =PROPER(in!E2) -> Blender | F2: =PROPER(in!F2) -> Home | G2: =in!G2 -> 3 | H2: =IF(ISNUMBER(in!H2),in!H2,"") -> 38 | I2: =IF(in!I2="","unknown",in!I2) -> Cash on Delivery | J2: =in!J2 -> Shipped | K2: =IFERROR(G2*H2,0) -> 114
A3: =in!A3 -> 101 | B3: =TRIM(in!B3) -> Customer_101 | C3: =in!C3 -> ORD-35783 | D3: =IFERROR(DATEVALUE(in!D3),in!D3) -> 45784 | E3: =PROPER(in!E3) -> Smartphone | F3: =PROPER(in!F3) -> Electronics | G3: =in!G3 -> 2 | H3: 0 | I3: =IF(in!I3="","unknown",in!I3) -> PayPal | J3: =in!J3 -> Processing | K3: =IFERROR(G3*H3,0) -> 0
A4: =in!A4 -> 102 | B4: =TRIM(in!B4) -> Customer_102 | C4: =in!C4 -> ORD-84355 | D4: =IFERROR(DATEVALUE(in!D4),in!D4) -> 12/23/2024 | E4: =PROPER(in!E4) -> Tennis Racket | F4: =PROPER(in!F4) -> Sports | G4: =in!G4 -> 1 | H4: =IF(ISNUMBER(in!H4),in!H4,"") -> 389.05 | I4: =IF(in!I4="","unknown",in!I4) -> PayPal | J4: =in!J4 -> Delivered | K4: =IFERROR(G4*H4,0) -> 389.05
A5: =in!A5 -> 103 | B5: =TRIM(in!B5) -> Customer_103 | C5: =in!C5 -> ORD-57811 | D5: =IFERROR(DATEVALUE(in!D5),in!D5) -> 3/19/2025 | E5: =PROPER(in!E5) -> Science | F5: =PROPER(in!F5) -> Books | G5: =in!G5 -> 5 | H5: =IF(ISNUMBER(in!H5),in!H5,"") -> 233.92 | I5: =IF(in!I5="","unknown",in!I5) -> PayPal | J5: =in!J5 -> Processing | K5: =IFERROR(G5*H5,0) -> 1169.6
A6: =in!A6 -> 104 | B6: =TRIM(in!B6) -> Customer_104 | C6: =in!C6 -> ORD-93614 | D6: =IFERROR(DATEVALUE(in!D6),in!D6) -> 10/20/2025 | E6: =PROPER(in!E6) -> Biography | F6: =PROPER(in!F6) -> Books | G6: =in!G6 -> 1 | H6: =IF(ISNUMBER(in!H6),in!H6,"") -> 552.51 | I6: =IF(in!I6="","unknown",in!I6) -> Cash on Delivery | J6: =in!J6 -> Processing | K6: =IFERROR(G6*H6,0) -> 552.51
A7: =in!A7 -> 105 | B7: =TRIM(in!B7) -> Customer_105 | C7: =in!C7 -> ORD-22442 | D7: =IFERROR(DATEVALUE(in!D7),in!D7) -> 11/20/2024 | E7: =PROPER(in!E7) -> Tennis Racket | F7: =PROPER(in!F7) -> Sports | G7: =in!G7 -> 3 | H7: =IF(ISNUMBER(in!H7),in!H7,"") -> 122.06 | I7: =IF(in!I7="","unknown",in!I7) -> Cash on Delivery | J7: =in!J7 -> Cancelled | K7: =IFERROR(G7*H7,0) -> 366.18
A8: =in!A8 -> 106 | B8: =TRIM(in!B8) -> Customer_106 | C8: =in!C8 -> ORD-25885 | D8: =IFERROR(DATEVALUE(in!D8),in!D8) -> 45690 | E8: =PROPER(in!E8) -> Blender | F8: =PROPER(in!F8) -> Home | G8: =in!G8 -> 0 | H8: =IF(ISNUMBER(in!H8),in!H8,"") -> 978.63 | I8: =IF(in!I8="","unknown",in!I8) -> Bank Transfer | J8: =in!J8 -> Processing | K8: =IFERROR(G8*H8,0) -> 0
A9: =in!A9 -> 107 | B9: =TRIM(in!B9) -> Customer_107 | C9: =in!C9 -> ORD-89122 | D9: =IFERROR(DATEVALUE(in!D9),in!D9) -> 45717 | E9: =PROPER(in!E9) -> Biography | F9: =PROPER(in!F9) -> Books | G9: =in!G9 -> 5 | H9: =IF(ISNUMBER(in!H9),in!H9,"") -> 587.68 | I9: =IF(in!I9="","unknown",in!I9) -> PayPal | J9: =in!J9 -> Returned | K9: =IFERROR(G9*H9,0) -> 2938.4
A10: =in!A10 -> 108 | B10: =TRIM(in!B10) -> Customer_108 | C10: =in!C10 -> ORD-64400 | D10: =IFERROR(DATEVALUE(in!D10),in!D10) -> 10/23/2025 | E10: =PROPER(in!E10) -> Science | F10: =PROPER(in!F10) -> Books | G10: =in!G10 -> 1 | H10: =IF(ISNUMBER(in!H10),in!H10,"") -> 600.29 | I10: =IF(in!I10="","unknown",in!I10) -> Cash on Delivery | J10: =in!J10 -> Processing | K10: =IFERROR(G10*H10,0) -> 600.29
A11: =in!A11 -> 109 | B11: =TRIM(in!B11) -> Customer_109 | C11: =in!C11 -> ORD-18512 | D11: =IFERROR(DATEVALUE(in!D11),in!D11) -> 45721 | E11: =PROPER(in!E11) -> Tennis Racket | F11: =PROPER(in!F11) -> Sports | G11: =in!G11 -> 5 | H11: =IF(ISNUMBER(in!H11),in!H11,"") -> 168.34 | I11: =IF(in!I11="","unknown",in!I11) -> Credit Card | J11: =in!J11 -> Shipped | K11: =IFERROR(G11*H11,0) -> 841.7
A12: =in!A12 -> 110 | B12: =TRIM(in!B12) -> Customer_110 | C12: =in!C12 -> ORD-61020 | D12: =IFERROR(DATEVALUE(in!D12),in!D12) -> 9/26/2025 | E12: =PROPER(in!E12) -> Basketball | F12: =PROPER(in!F12) -> Sports | G12: =in!G12 -> 5 | H12: 400 | I12: =IF(in!I12="","unknown",in!I12) -> Cash on Delivery | J12: =in!J12 -> Cancelled | K12: =IFERROR(G12*H12,0) -> 2000
A13: =in!A13 -> 111 | B13: =TRIM(in!B13) -> Customer_111 | C13: =in!C13 -> ORD-72349 | D13: =IFERROR(DATEVALUE(in!D13),in!D13) -> 10/22/2025 | E13: =PROPER(in!E13) -> Comics | F13: =PROPER(in!F13) -> Books | G13: =in!G13 -> 2 | H13: =IF(ISNUMBER(in!H13),in!H13,"") -> 865.77 | I13: =IF(in!I13="","unknown",in!I13) -> Credit Card | J13: =in!J13 -> Returned | K13: =IFERROR(G13*H13,0) -> 1731.54
A14: =in!A14 -> 112 | B14: =TRIM(in!B14) -> Customer_112 | C14: =in!C14 -> ORD-80867 | D14: =IFERROR(DATEVALUE(in!D14),in!D14) -> 45691 | E14: =PROPER(in!E14) -> Shoes | F14: =PROPER(in!F14) -> Clothing | G14: =in!G14 -> 4 | H14: =IF(ISNUMBER(in!H14),in!H14,"") -> 752.13 | I14: =IF(in!I14="","unknown",in!I14) -> Bank Transfer | J14: =in!J14 -> Delivered | K14: =IFERROR(G14*H14,0) -> 3008.52
A15: =in!A15 -> 113 | B15: =TRIM(in!B15) -> Customer_113 | C15: =in!C15 -> ORD-23994 | D15: =IFERROR(DATEVALUE(in!D15),in!D15) -> 7/24/2025 | E15: =PROPER(in!E15) -> Fiction | F15: =PROPER(in!F15) -> Books | G15: =in!G15 -> 1 | H15: =IF(ISNUMBER(in!H15),in!H15,"") -> 411.81 | I15: =IF(in!I15="","unknown",in!I15) -> Credit Card | J15: =in!J15 -> Processing | K15: =IFERROR(G15*H15,0) -> 411.81
A16: =in!A16 -> 114 | B16: =TRIM(in!B16) -> Customer_114 | C16: =in!C16 -> ORD-77417 | D16: 45047 | E16: =PROPER(in!E16) -> Smartphone | F16: =PROPER(in!F16) -> Electronics | G16: =in!G16 -> 2 | H16: =IF(ISNUMBER(in!H16),in!H16,"") -> 413.13 | I16: =IF(in!I16="","unknown",in!I16) -> Cash on Delivery | J16: =in!J16 -> Shipped | K16: =IFERROR(G16*H16,0) -> 826.26
A17: =in!A17 -> 115 | B17: =TRIM(in!B17) -> Customer_115 | C17: =in!C17 -> ORD-72778 | D17: =IFERROR(DATEVALUE(in!D17),in!D17) -> 45931 | E17: =PROPER(in!E17) -> Fiction | F17: =PROPER(in!F17) -> Books | G17: =in!G17 -> 2 | H17: =IF(ISNUMBER(in!H17),in!H17,"") -> 796.84 | I17: =IF(in!I17="","unknown",in!I17) -> Cash on Delivery | J17: =in!J17 -> Returned | K17: =IFERROR(G17*H17,0) -> 1593.68
A18: =in!A18 -> 116 | B18: =TRIM(in!B18) -> Customer_116 | C18: =in!C18 -> ORD-63660 | D18: =IFERROR(DATEVALUE(in!D18),in!D18) -> 10/30/2025 | E18: =PROPER(in!E18) -> Microwave | F18: =PROPER(in!F18) -> Home | G18: =in!G18 -> 4 | H18: 0 | I18: =IF(in!I18="","unknown",in!I18) -> Cash on Delivery | J18: =in!J18 -> Processing | K18: =IFERROR(G18*H18,0) -> 0
A19: =in!A19 -> 117 | B19: =TRIM(in!B19) -> Customer_117 | C19: =in!C19 -> ORD-72751 | D19: =IFERROR(DATEVALUE(in!D19),in!D19) -> 45993 | E19: =PROPER(in!E19) -> Blender | F19: Electronics | G19: 2 | H19: =IF(ISNUMBER(in!H19),in!H19,"") -> 10000 | I19: =IF(in!I19="","unknown",in!I19) -> Cash on Delivery | J19: =in!J19 -> Processing | K19: =IFERROR(G19*H19,0) -> 20000
A20: =in!A20 -> 118 | B20: =TRIM(in!B20) -> Customer_118 | C20: =in!C20 -> ORD-96061 | D20: =IFERROR(DATEVALUE(in!D20),in!D20) -> 5/31/2025 | E20: =PROPER(in!E20) -> Science | F20: =PROPER(in!F20) -> Books | G20: =in!G20 -> 5 | H20: =IF(ISNUMBER(in!H20),in!H20,"") -> 247.82 | I20: =IF(in!I20="","unknown",in!I20) -> PayPal | J20: =in!J20 -> Processing | K20: =IFERROR(G20*H20,0) -> 1239.1
A21: =in!A21 -> 119 | B21: =TRIM(in!B21) -> Customer_119 | C21: =in!C21 -> ORD-76016 | D21: =IFERROR(DATEVALUE(in!D21),in!D21) -> 12/19/2024 | E21: =PROPER(in!E21) -> Basketball | F21: =PROPER(in!F21) -> Sports | G21: =in!G21 -> 4 | H21: =IF(ISNUMBER(in!H21),in!H21,"") -> 438.19 | I21: =IF(in!I21="","unknown",in!I21) -> Cash on Delivery | J21: =in!J21 -> Processing | K21: =IFERROR(G21*H21,0) -> 1752.76
A22: =in!A22 -> 120 | B22: =TRIM(in!B22) -> Customer_120 | C22: =in!C22 -> ORD-14659 | D22: =IFERROR(DATEVALUE(in!D22),in!D22) -> 6/13/2025 | E22: =PROPER(in!E22) -> Yoga Mat | F22: =PROPER(in!F22) -> Electronics | G22: =in!G22 -> 5 | H22: 0 | I22: =IF(in!I22="","unknown",in!I22) -> Credit Card | J22: =in!J22 -> Cancelled | K22: =IFERROR(G22*H22,0) -> 0
A23: =in!A23 -> 121 | B23: =TRIM(in!B23) -> Customer_121 | C23: =in!C23 -> ORD-80067 | D23: =IFERROR(DATEVALUE(in!D23),in!D23) -> 45971 | E23: =PROPER(in!E23) -> Basketball | F23: =PROPER(in!F23) -> Sports | G23: =in!G23 -> 4 | H23: =IF(ISNUMBER(in!H23),in!H23,"") -> 523.01 | I23: =IF(in!I23="","unknown",in!I23) -> Credit Card | J23: =in!J23 -> Delivered | K23: =IFERROR(G23*H23,0) -> 2092.04
A24: =in!A24 -> 122 | B24: =TRIM(in!B24) -> Customer_122 | C24: =in!C24 -> ORD-21443 | D24: =IFERROR(DATEVALUE(in!D24),in!D24) -> 5/16/2025 | E24: =PROPER(in!E24) -> Microwave | F24: =PROPER(in!F24) -> Home | G24: =in!G24 -> 2 | H24: =IF(ISNUMBER(in!H24),in!H24,"") -> 556.93 | I24: =IF(in!I24="","unknown",in!I24) -> PayPal | J24: =in!J24 -> Shipped | K24: =IFERROR(G24*H24,0) -> 1113.86
A25: =in!A25 -> 123 | B25: =TRIM(in!B25) -> Customer_123 | C25: =in!C25 -> ORD-11314 | D25: =IFERROR(DATEVALUE(in!D25),in!D25) -> 45818 | E25: =PROPER(in!E25) -> Vacuum | F25: Electronics | G25: =in!G25 -> 3 | H25: =IF(ISNUMBER(in!H25),in!H25,"") -> 615.91 | I25: =IF(in!I25="","unknown",in!I25) -> Cash on Delivery | J25: =in!J25 -> Cancelled | K25: =IFERROR(G25*H25,0) -> 1847.73
A26: =in!A26 -> 124 | B26: =TRIM(in!B26) -> Customer_124 | C26: =in!C26 -> ORD-46136 | D26: =IFERROR(DATEVALUE(in!D26),in!D26) -> 5/31/2025 | E26: =PROPER(in!E26) -> Comics | F26: =PROPER(in!F26) -> Books | G26: =in!G26 -> 5 | H26: 0 | I26: =IF(in!I26="","unknown",in!I26) -> PayPal | J26: =in!J26 -> Cancelled | K26: =IFERROR(G26*H26,0) -> 0
A27: =in!A27 -> 125 | B27: =TRIM(in!B27) -> Customer_125 | C27: =in!C27 -> ORD-23202 | D27: =IFERROR(DATEVALUE(in!D27),in!D27) -> 45902 | E27: =PROPER(in!E27) -> Comics | F27: =PROPER(in!F27) -> Books | G27: =in!G27 -> 4 | H27: =IF(ISNUMBER(in!H27),in!H27,"") -> 765.69 | I27: =IF(in!I27="","unknown",in!I27) -> PayPal | J27: =in!J27 -> Shipped | K27: =IFERROR(G27*H27,0) -> 3062.76
A28: =in!A28 -> 126 | B28: =TRIM(in!B28) -> Customer_126 | C28: =in!C28 -> ORD-11261 | D28: =IFERROR(DATEVALUE(in!D28),in!D28) -> 5/18/2025 | E28: =PROPER(in!E28) -> Shoes | F28: =PROPER(in!F28) -> Clothing | G28: =in!G28 -> 4 | H28: =IF(ISNUMBER(in!H28),in!H28,"") -> 836.8 | I28: =IF(in!I28="","unknown",in!I28) -> Bank Transfer | J28: =in!J28 -> Cancelled | K28: =IFERROR(G28*H28,0) -> 3347.2
A29: =in!A29 -> 127 | B29: =TRIM(in!B29) -> Customer_127 | C29: =in!C29 -> ORD-65482 | D29: =IFERROR(DATEVALUE(in!D29),in!D29) -> 45996 | E29: =PROPER(in!E29) -> Blender | F29: =PROPER(in!F29) -> Home | G29: =in!G29 -> 5 | H29: =IF(ISNUMBER(in!H29),in!H29,"") -> 336.02 | I29: =IF(in!I29="","unknown",in!I29) -> Bank Transfer | J29: =in!J29 -> Returned | K29: =IFERROR(G29*H29,0) -> 1680.1
A30: =in!A30 -> 128 | B30: =TRIM(in!B30) -> Customer_128 | C30: =in!C30 -> ORD-12270 | D30: =IFERROR(DATEVALUE(in!D30),in!D30) -> 45576 | E30: =PROPER(in!E30) -> Lamp | F30: =PROPER(in!F30) -> Electronics | G30: =in!G30 -> 3 | H30: =IF(ISNUMBER(in!H30),in!H30,"") -> 898.69 | I30: =IF(in!I30="","unknown",in!I30) -> Bank Transfer | J30: =in!J30 -> Delivered | K30: =IFERROR(G30*H30,0) -> 2696.07
A31: =in!A31 -> 129 | B31: =TRIM(in!B31) -> Customer_129 | C31: =in!C31 -> ORD-48863 | D31: =IFERROR(DATEVALUE(in!D31),in!D31) -> 6/22/2025 | E31: =PROPER(in!E31) -> Science | F31: =PROPER(in!F31) -> Books | G31: =in!G31 -> 4 | H31: =IF(ISNUMBER(in!H31),in!H31,"") -> 736.71 | I31: =IF(in!I31="","unknown",in!I31) -> Bank Transfer | J31: =in!J31 -> Returned | K31: =IFERROR(G31*H31,0) -> 2946.84
A32: =in!A32 -> 130 | B32: =TRIM(in!B32) -> Customer_130 | C32: =in!C32 -> ORD-34007 | D32: =IFERROR(DATEVALUE(in!D32),in!D32) -> 8/15/2025 | E32: =PROPER(in!E32) -> Tennis Racket | F32: =PROPER(in!F32) -> Sports | G32: =in!G32 -> 2 | H32: 0 | I32: =IF(in!I32="","unknown",in!I32) -> Bank Transfer | J32: =in!J32 -> Processing | K32: =IFERROR(G32*H32,0) -> 0
A33: =in!A33 -> 131 | B33: =TRIM(in!B33) -> Customer_131 | C33: =in!C33 -> ORD-91396 | D33: =IFERROR(DATEVALUE(in!D33),in!D33) -> 45967 | E33: =PROPER(in!E33) -> Lamp | F33: =PROPER(in!F33) -> Home | G33: =in!G33 -> 5 | H33: =IF(ISNUMBER(in!H33),in!H33,"") -> 616.63 | I33: =IF(in!I33="","unknown",in!I33) -> PayPal | J33: =in!J33 -> Shipped | K33: =IFERROR(G33*H33,0) -> 3083.15
A34: =in!A34 -> 132 | B34: =TRIM(in!B34) -> Customer_132 | C34: =in!C34 -> ORD-40186 | D34: =IFERROR(DATEVALUE(in!D34),in!D34) -> 45692 | E34: =PROPER(in!E34) -> Yoga Mat | F34: =PROPER(in!F34) -> Electronics | G34: =in!G34 -> 1 | H34: =IF(ISNUMBER(in!H34),in!H34,"") -> 266.7 | I34: =IF(in!I34="","unknown",in!I34) -> PayPal | J34: =in!J34 -> Delivered | K34: =IFERROR(G34*H34,0) -> 266.7
A35: =in!A35 -> 133 | B35: =TRIM(in!B35) -> Customer_133 | C35: =in!C35 -> ORD-68182 | D35: =IFERROR(DATEVALUE(in!D35),in!D35) -> 45424 | E35: =PROPER(in!E35) -> Biography | F35: Electronics | G35: =in!G35 -> 5 | H35: =IF(ISNUMBER(in!H35),in!H35,"") -> 343.24 | I35: =IF(in!I35="","unknown",in!I35) -> Credit Card | J35: =in!J35 -> Shipped | K35: =IFERROR(G35*H35,0) -> 1716.2
A36: =in!A36 -> 134 | B36: =TRIM(in!B36) -> Customer_134 | C36: =in!C36 -> ORD-16585 | D36: =IFERROR(DATEVALUE(in!D36),in!D36) -> 45757 | E36: =PROPER(in!E36) -> T-Shirt | F36: =PROPER(in!F36) -> Clothing | G36: 5 | H36: =IF(ISNUMBER(in!H36),in!H36,"") -> 591.53 | I36: =IF(in!I36="","unknown",in!I36) -> PayPal | J36: =in!J36 -> Shipped | K36: =IFERROR(G36*H36,0) -> 2957.65
A37: =in!A37 -> 135 | B37: =TRIM(in!B37) -> Customer_135 | C37: =in!C37 -> ORD-33656 | D37: =IFERROR(DATEVALUE(in!D37),in!D37) -> 45902 | E37: =PROPER(in!E37) -> Smartwatch | F37: =PROPER(in!F37) -> Electronics | G37: =in!G37 -> 4 | H37: =IF(ISNUMBER(in!H37),in!H37,"") -> 446.19 | I37: =IF(in!I37="","unknown",in!I37) -> Cash on Delivery | J37: =in!J37 -> Cancelled | K37: =IFERROR(G37*H37,0) -> 1784.76
A38: =in!A38 -> 136 | B38: =TRIM(in!B38) -> Customer_136 | C38: =in!C38 -> ORD-20985 | D38: =IFERROR(DATEVALUE(in!D38),in!D38) -> 45997 | E38: =PROPER(in!E38) -> Headphones | F38: Electronics | G38: =in!G38 -> 1 | H38: =IF(ISNUMBER(in!H38),in!H38,"") -> 696.71 | I38: =IF(in!I38="","unknown",in!I38) -> Credit Card | J38: =in!J38 -> Delivered | K38: =IFERROR(G38*H38,0) -> 696.71
A39: =in!A39 -> 137 | B39: =TRIM(in!B39) -> Customer_137 | C39: =in!C39 -> ORD-91254 | D39: =IFERROR(DATEVALUE(in!D39),in!D39) -> 2/23/2025 | E39: =PROPER(in!E39) -> Vacuum | F39: =PROPER(in!F39) -> Home | G39: =in!G39 -> 3 | H39: 100 | I39: =IF(in!I39="","unknown",in!I39) -> Cash on Delivery | J39: =in!J39 -> Delivered | K39: =IFERROR(G39*H39,0) -> 300
A40: =in!A40 -> 138 | B40: =TRIM(in!B40) -> Customer_138 | C40: =in!C40 -> ORD-34319 | D40: =IFERROR(DATEVALUE(in!D40),in!D40) -> 45908 | E40: =PROPER(in!E40) -> Lamp | F40: =PROPER(in!F40) -> Home | G40: =in!G40 -> 1 | H40: =IF(ISNUMBER(in!H40),in!H40,"") -> 531.06 | I40: =IF(in!I40="","unknown",in!I40) -> PayPal | J40: =in!J40 -> Processing | K40: =IFERROR(G40*H40,0) -> 531.06
...

Sheet analysis
A3: Category | B3: Sum of Total
A4: Books | B4: 38357.11
A5: Clothing | B5: 32644.38
A6: Electronics | B6: 43678.55
A7: Home | B7: 26023.73
A8: Sports | B8: 19736.25
A9: Grand Total | B9: 160440.02

Sheet analysis 2
A3: Status | B3: Count of Order_ID
A4: Cancelled | B4: 15
A5: Delivered | B5: 11
A6: Processing | B6: 27
A7: Returned | B7: 26
A8: Shipped | B8: 23
A9: Grand Total | B9: 102

Sheet analysis 3
A3: Payment_Method | B3: Sum of Total
A4: Bank Transfer | B4: 43023.67
A5: Cash on Delivery | B5: 64758.3
A6: Credit Card | B6: 25077.63
A7: PayPal | B7: 27580.42
A8: Grand Total | B8: 160440.02

Sheet dashboard
A1: E-Commerce Sales & Operations performance Dashboard
B3: TOTAL REVENUE | E3: TOTAL ORDERS | H3: AVERAGE ORDER VALUE
B4: =SUM('clean data'!K:K) -> 160440.02 | E4: =COUNTA('clean data'!B:B) -> 103 | H4: =B4/E4 -> 1557.6701
